[
  {
    "number": 20,
    "title": "Failed to run in docker wsl",
    "created_at": "2025-01-10T17:47:56Z",
    "closed_at": "2025-01-10T17:52:54Z",
    "labels": [],
    "url": "https://github.com/remsky/Kokoro-FastAPI/issues/20",
    "body": "Trying to run it on docker on wsl and I keep getting this error:\r\n``` bash\r\nkokoro-fastapi-kokoro-tts-1     | ERROR:    Traceback (most recent call last):\r\nkokoro-fastapi-kokoro-tts-1     |   File \"/usr/local/lib/python3.10/dist-packages/starlette/routing.py\", line 693, in lifespan\r\nkokoro-fastapi-kokoro-tts-1     |     async with self.lifespan_context(app) as maybe_state:\r\nkokoro-fastapi-kokoro-tts-1     |   File \"/usr/lib/python3.10/contextlib.py\", line 199, in __aenter__\r\nkokoro-fastapi-kokoro-tts-1     |     return await anext(self.gen)\r\nkokoro-fastapi-kokoro-tts-1     |   File \"/usr/local/lib/python3.10/dist-packages/fastapi/routing.py\", line 133, in merged_lifespan\r\nkokoro-fastapi-kokoro-tts-1     |     async with original_context(app) as maybe_original_state:\r\nkokoro-fastapi-kokoro-tts-1     |   File \"/usr/lib/python3.10/contextlib.py\", line 199, in __aenter__\r\nkokoro-fastapi-kokoro-tts-1     |     return await anext(self.gen)\r\nkokoro-fastapi-kokoro-tts-1     |   File \"/usr/local/lib/python3.10/dist-packages/fastapi/routing.py\", line 133, in merged_lifespan\r\nkokoro-fastapi-kokoro-tts-1     |     async with original_context(app) as maybe_original_state:\r\nkokoro-fastapi-kokoro-tts-1     |   File \"/usr/lib/python3.10/contextlib.py\", line 199, in __aenter__\r\nkokoro-fastapi-kokoro-tts-1     |     return await anext(self.gen)\r\nkokoro-fastapi-kokoro-tts-1     |   File \"/app/api/src/main.py\", line 52, in lifespan\r\nkokoro-fastapi-kokoro-tts-1     |     voicepack_count = await TTSModel.setup()\r\nkokoro-fastapi-kokoro-tts-1     |   File \"/app/api/src/services/tts_base.py\", line 46, in setup\r\nkokoro-fastapi-kokoro-tts-1     |     os.makedirs(cls.VOICES_DIR, exist_ok=True)\r\nkokoro-fastapi-kokoro-tts-1     |   File \"/usr/lib/python3.10/os.py\", line 225, in makedirs\r\nkokoro-fastapi-kokoro-tts-1     |     mkdir(name, mode)\r\nkokoro-fastapi-kokoro-tts-1     | PermissionError: [Errno 13] Permission denied: '/app/api/src/voices'\r\nkokoro-fastapi-kokoro-tts-1     |\r\nkokoro-fastapi-kokoro-tts-1     | ERROR:    Application startup failed. Exiting.\r\nkokoro-fastapi-kokoro-tts-1 exited with code 3\r\n```\r\n\r\nThe model-fetcher and gradio-ui containers seem to be running fine but the kokoro-tts container crashes as soon as it starts.\r\nAlso in gradio, I just see a message saying \"TTS service: Waiting for service...\"",
    "comments_url": "https://api.github.com/repos/remsky/Kokoro-FastAPI/issues/20/comments",
    "author": "ronneldavis",
    "comments": [
      {
        "user": "lsnch",
        "created_at": "2025-01-14T04:41:30Z",
        "body": "had the same issue on arch.\r\nreconnected ssh, restarted tmux = resolved. \r\nit was probably permissions at some level, even though i was root."
      },
      {
        "user": "ronneldavis",
        "created_at": "2025-01-16T14:40:56Z",
        "body": "Yeap that's exactly what fixed my issue as well, not sure why it was happening even as root but a restart fixed it"
      }
    ],
    "satisfaction_conditions": [
      "Resolve directory permission issues preventing the TTS service from creating '/app/api/src/voices'",
      "Ensure Docker environment maintains proper filesystem permissions between host (WSL) and container",
      "Address unexpected permission behavior even when running as root",
      "Ensure TTS service dependency on voices directory is properly initialized before service start"
    ],
    "_classification": {
      "category": "Can be dockerized without any issue",
      "timestamp": "2025-04-05 02:11:34"
    }
  }
]