[
  {
    "number": 325,
    "title": "Stuck in loop when trying to build docker container",
    "created_at": "2025-02-04T08:33:18Z",
    "closed_at": "2025-02-08T09:55:01Z",
    "labels": [],
    "url": "https://github.com/cocktailpeanut/fluxgym/issues/325",
    "body": "Following the install guide for docker, when I attempt to run `docker compose up -d --build` running `docker ps` showed the container was stuck in a boot loop. Removing the `-d` from the build I received this error\n\n` \u2714 Network fluxgym_default  Created                                                                                                                     0.1s\n \u2714 Container fluxgym        Created                                                                                                                     0.1s\nAttaching to fluxgym\n\nfluxgym  | Traceback (most recent call last):\n\nfluxgym  |   File \"/usr/local/lib/python3.10/dist-packages/diffusers/utils/import_utils.py\", line 943, in _get_module\n\nfluxgym  |     return importlib.import_module(\".\" + module_name, self.__name__)\n\nfluxgym  |   File \"/usr/lib/python3.10/importlib/__init__.py\", line 126, in import_module\n\nfluxgym  |     return _bootstrap._gcd_import(name[level:], package, level)\n\nfluxgym  |   File \"<frozen importlib._bootstrap>\", line 1050, in _gcd_import\n\nfluxgym  |   File \"<frozen importlib._bootstrap>\", line 1027, in _find_and_load\n\nfluxgym  |   File \"<frozen importlib._bootstrap>\", line 1006, in _find_and_load_unlocked\n\nfluxgym  |   File \"<frozen importlib._bootstrap>\", line 688, in _load_unlocked\n\nfluxgym  |   File \"<frozen importlib._bootstrap_external>\", line 883, in exec_module\n\nfluxgym  |   File \"<frozen importlib._bootstrap>\", line 241, in _call_with_frames_removed\n\nfluxgym  |   File \"/usr/local/lib/python3.10/dist-packages/diffusers/loaders/single_file.py\", line 24, in <module>\n\nfluxgym  |     from .single_file_utils import (\n\nfluxgym  |   File \"/usr/local/lib/python3.10/dist-packages/diffusers/loaders/single_file_utils.py\", line 28, in <module>\n\nfluxgym  |     from ..models.modeling_utils import load_state_dict\n\nfluxgym  |   File \"/usr/local/lib/python3.10/dist-packages/diffusers/models/modeling_utils.py\", line 37, in <module>\n\nfluxgym  |     from ..quantizers import DiffusersAutoQuantizer, DiffusersQuantizer\n\nfluxgym  |   File \"/usr/local/lib/python3.10/dist-packages/diffusers/quantizers/__init__.py\", line 15, in <module>\n\nfluxgym  |     from .auto import DiffusersAutoQuantizer\n\nfluxgym  |   File \"/usr/local/lib/python3.10/dist-packages/diffusers/quantizers/auto.py\", line 22, in <module>\n\nfluxgym  |     from .bitsandbytes import BnB4BitDiffusersQuantizer, BnB8BitDiffusersQuantizer\n\nfluxgym  |   File \"/usr/local/lib/python3.10/dist-packages/diffusers/quantizers/bitsandbytes/__init__.py\", line 2, in <module>\n\nfluxgym  |     from .utils import dequantize_and_replace, dequantize_bnb_weight, replace_with_bnb_linear\n\nfluxgym  |   File \"/usr/local/lib/python3.10/dist-packages/diffusers/quantizers/bitsandbytes/utils.py\", line 32, in <module>\n\nfluxgym  |     import bitsandbytes as bnb\n\nfluxgym  |   File \"/usr/local/lib/python3.10/dist-packages/bitsandbytes/__init__.py\", line 15, in <module>\n\nfluxgym  |     from .nn import modules\n\nfluxgym  |   File \"/usr/local/lib/python3.10/dist-packages/bitsandbytes/nn/__init__.py\", line 21, in <module>\n\nfluxgym  |     from .triton_based_modules import (\n\nfluxgym  |   File \"/usr/local/lib/python3.10/dist-packages/bitsandbytes/nn/triton_based_modules.py\", line 7, in <module>\n\nfluxgym  |     from bitsandbytes.triton.int8_matmul_mixed_dequantize import (\n\nfluxgym  |   File \"/usr/local/lib/python3.10/dist-packages/bitsandbytes/triton/int8_matmul_mixed_dequantize.py\", line 12, in <module>\n\nfluxgym  |     from triton.ops.matmul_perf_model import early_config_prune, estimate_matmul_time\n\nfluxgym  | ModuleNotFoundError: No module named 'triton.ops'\n`\n\nI inserted `triton` into the list of packages to be installed by `pip` in the Dockerfile. I ran `docker build --no-cache` to rebuild everything, and saw triton being installed in one of the steps. However I still receive the exact same error message, and I can't seem to find any answers on Google how to fix this. Any help would be appreciated.",
    "comments_url": "https://api.github.com/repos/cocktailpeanut/fluxgym/issues/325/comments",
    "author": "gavanpang",
    "comments": [
      {
        "user": "aaron-pak",
        "created_at": "2025-02-05T23:36:38Z",
        "body": "Can confirm having the same issue"
      },
      {
        "user": "namila007",
        "created_at": "2025-02-07T20:32:17Z",
        "body": "having the same issue\n\n---\n\nfixed the issue by adding this after line 32 on DockerFile\n  `RUN pip install --upgrade --force-reinstall triton==2.1.0`"
      },
      {
        "user": "echostorm",
        "created_at": "2025-02-08T00:18:04Z",
        "body": "thanks was facing same issue, works after adding triton."
      },
      {
        "user": "gavanpang",
        "created_at": "2025-02-08T09:55:01Z",
        "body": "Thank you for the solution, it's working now!"
      }
    ],
    "satisfaction_conditions": [
      "Ensures the triton Python package is installed in a way that resolves the ModuleNotFoundError for 'triton.ops'",
      "Explains why simply adding 'triton' to requirements might not work as expected",
      "Addresses compatibility between triton version and other dependencies",
      "Provides a mechanism to force proper installation of required components"
    ],
    "_classification": {
      "category": "Can be dockerized without any issue",
      "timestamp": "2025-04-05 01:59:03"
    }
  },
  {
    "number": 231,
    "title": "Runner: <LogsViewRunner nb_logs=56 exit_code=1>",
    "created_at": "2024-11-01T14:25:10Z",
    "closed_at": "2024-11-07T00:17:36Z",
    "labels": [],
    "url": "https://github.com/cocktailpeanut/fluxgym/issues/231",
    "body": "2024-11-01 17:58:06] [INFO] To avoid this warning pass in values for each of the problematic parameters or run accelerate config.\r\n[2024-11-01 17:58:10] [INFO] 2024-11-01 17:58:10 INFO     highvram is enabled /           train_util.py:4106\r\n[2024-11-01 17:58:10] [INFO] highvram\u304c\u6709\u52b9\u3067\u3059\r\n[2024-11-01 17:58:10] [INFO] WARNING  cache_latents_to_disk is        train_util.py:4123\r\n[2024-11-01 17:58:10] [INFO] enabled, so cache_latents is\r\n[2024-11-01 17:58:10] [INFO] also enabled /\r\n[2024-11-01 17:58:10] [INFO] cache_latents_to_disk\u304c\u6709\u52b9\u306a\u305f\r\n[2024-11-01 17:58:10] [INFO] \u3081\u3001cache_latents\u3092\u6709\u52b9\u306b\u3057\u307e\u3059\r\n[2024-11-01 17:58:10] [INFO] 2024-11-01 17:58:10 INFO     Checking the state dict:          flux_utils.py:62\r\n[2024-11-01 17:58:10] [INFO] Diffusers or BFL, dev or schnell\r\n[2024-11-01 17:58:10] [INFO] INFO     t5xxl_max_token_length:  flux_train_network.py:152\r\n[2024-11-01 17:58:10] [INFO] 512\r\n[2024-11-01 17:58:10] [INFO] Traceback (most recent call last):\r\n[2024-11-01 17:58:10] [INFO] File \"E:\\fluxgym\\sd-scripts\\flux_train_network.py\", line 564, in <module>\r\n[2024-11-01 17:58:10] [INFO] trainer.train(args)\r\n[2024-11-01 17:58:10] [INFO] File \"E:\\fluxgym\\sd-scripts\\train_network.py\", line 292, in train\r\n[2024-11-01 17:58:10] [INFO] tokenize_strategy = self.get_tokenize_strategy(args)\r\n[2024-11-01 17:58:10] [INFO] File \"E:\\fluxgym\\sd-scripts\\flux_train_network.py\", line 153, in get_tokenize_strategy\r\n[2024-11-01 17:58:10] [INFO] return strategy_flux.FluxTokenizeStrategy(t5xxl_max_token_length, args.tokenizer_cache_dir)\r\n[2024-11-01 17:58:10] [INFO] File \"E:\\fluxgym\\sd-scripts\\library\\strategy_flux.py\", line 26, in __init__\r\n[2024-11-01 17:58:10] [INFO] self.clip_l = self._load_tokenizer(CLIPTokenizer, CLIP_L_TOKENIZER_ID, tokenizer_cache_dir=tokenizer_cache_dir)\r\n[2024-11-01 17:58:10] [INFO] File \"E:\\fluxgym\\sd-scripts\\library\\strategy_base.py\", line 65, in _load_tokenizer\r\n[2024-11-01 17:58:10] [INFO] tokenizer = model_class.from_pretrained(model_id, subfolder=subfolder)\r\n[2024-11-01 17:58:10] [INFO] File \"E:\\fluxgym\\env\\lib\\site-packages\\transformers\\tokenization_utils_base.py\", line 2210, in from_pretrained\r\n[2024-11-01 17:58:10] [INFO] tokenizer_config = json.load(reader)\r\n[2024-11-01 17:58:10] [INFO] File \"C:\\Users\\Administrator\\AppData\\Local\\Programs\\Python\\Python310\\lib\\json\\__init__.py\", line 293, in load\r\n[2024-11-01 17:58:10] [INFO] return loads(fp.read(),\r\n[2024-11-01 17:58:10] [INFO] File \"C:\\Users\\Administrator\\AppData\\Local\\Programs\\Python\\Python310\\lib\\json\\__init__.py\", line 346, in loads\r\n[2024-11-01 17:58:10] [INFO] return _default_decoder.decode(s)\r\n[2024-11-01 17:58:10] [INFO] File \"C:\\Users\\Administrator\\AppData\\Local\\Programs\\Python\\Python310\\lib\\json\\decoder.py\", line 337, in decode\r\n[2024-11-01 17:58:10] [INFO] obj, end = self.raw_decode(s, idx=_w(s, 0).end())\r\n[2024-11-01 17:58:10] [INFO] File \"C:\\Users\\Administrator\\AppData\\Local\\Programs\\Python\\Python310\\lib\\json\\decoder.py\", line 355, in raw_decode\r\n[2024-11-01 17:58:10] [INFO] raise JSONDecodeError(\"Expecting value\", s, err.value) from None\r\n[2024-11-01 17:58:10] [INFO] json.decoder.JSONDecodeError: Expecting value: line 1 column 1 (char 0)\r\n[2024-11-01 17:58:11] [INFO] Traceback (most recent call last):\r\n[2024-11-01 17:58:11] [INFO] File \"C:\\Users\\Administrator\\AppData\\Local\\Programs\\Python\\Python310\\lib\\runpy.py\", line 196, in _run_module_as_main\r\n[2024-11-01 17:58:11] [INFO] return _run_code(code, main_globals, None,\r\n[2024-11-01 17:58:11] [INFO] File \"C:\\Users\\Administrator\\AppData\\Local\\Programs\\Python\\Python310\\lib\\runpy.py\", line 86, in _run_code\r\n[2024-11-01 17:58:11] [INFO] exec(code, run_globals)\r\n[2024-11-01 17:58:11] [INFO] File \"E:\\fluxgym\\env\\Scripts\\accelerate.exe\\__main__.py\", line 7, in <module>\r\n[2024-11-01 17:58:11] [INFO] sys.exit(main())\r\n[2024-11-01 17:58:11] [INFO] File \"E:\\fluxgym\\env\\lib\\site-packages\\accelerate\\commands\\accelerate_cli.py\", line 48, in main\r\n[2024-11-01 17:58:11] [INFO] args.func(args)\r\n[2024-11-01 17:58:11] [INFO] File \"E:\\fluxgym\\env\\lib\\site-packages\\accelerate\\commands\\launch.py\", line 1106, in launch_command\r\n[2024-11-01 17:58:11] [INFO] simple_launcher(args)\r\n[2024-11-01 17:58:11] [INFO] File \"E:\\fluxgym\\env\\lib\\site-packages\\accelerate\\commands\\launch.py\", line 704, in simple_launcher\r\n[2024-11-01 17:58:11] [INFO] raise subprocess.CalledProcessError(returncode=process.returncode, cmd=cmd)\r\n[2024-11-01 17:58:11] [INFO] subprocess.CalledProcessError: Command '['E:\\\\fluxgym\\\\env\\\\Scripts\\\\python.exe', 'sd-scripts/flux_train_network.py', '--pretrained_model_name_or_path', 'E:\\\\fluxgym\\\\models\\\\unet\\\\flux1-dev.sft', '--clip_l', 'E:\\\\fluxgym\\\\models\\\\clip\\\\clip_l.safetensors', '--t5xxl', 'E:\\\\fluxgym\\\\models\\\\clip\\\\t5xxl_fp16.safetensors', '--ae', 'E:\\\\fluxgym\\\\models\\\\vae\\\\ae.sft', '--cache_latents_to_disk', '--save_model_as', 'safetensors', '--sdpa', '--persistent_data_loader_workers', '--max_data_loader_n_workers', '2', '--seed', '42', '--gradient_checkpointing', '--mixed_precision', 'bf16', '--save_precision', 'bf16', '--network_module', 'networks.lora_flux', '--network_dim', '4', '--optimizer_type', 'adafactor', '--optimizer_args', 'relative_step=False', 'scale_parameter=False', 'warmup_init=False', '--lr_scheduler', 'constant_with_warmup', '--max_grad_norm', '0.0', '--learning_rate', '8e-4', '--cache_text_encoder_outputs', '--cache_text_encoder_outputs_to_disk', '--fp8_base', '--highvram', '--max_train_epochs', '16', '--save_every_n_epochs', '4', '--dataset_config', 'E:\\\\fluxgym\\\\outputs\\\\xb-lora\\\\dataset.toml', '--output_dir', 'E:\\\\fluxgym\\\\outputs\\\\xb-lora', '--output_name', 'xb-lora', '--timestep_sampling', 'shift', '--discrete_flow_shift', '3.1582', '--model_prediction_type', 'raw', '--guidance_scale', '1', '--loss_type', 'l2']' returned non-zero exit status 1.\r\n[2024-11-01 17:58:11] [ERROR] Command exited with code 1\r\n[2024-11-01 17:58:11] [INFO] Runner: <LogsViewRunner nb_logs=56 exit_code=1>",
    "comments_url": "https://api.github.com/repos/cocktailpeanut/fluxgym/issues/231/comments",
    "author": "lestersssss",
    "comments": [
      {
        "user": "Hiddengenie",
        "created_at": "2024-11-02T11:41:06Z",
        "body": "Check whether your ae.sft (in the vae folder) is complete and uncorrupted. If it is then try uploading an older version - I uploaded a version from September and that solved the isse. "
      },
      {
        "user": "alexnikospb",
        "created_at": "2024-11-06T18:25:03Z",
        "body": "I have the same problem:  Runner: LogsViewRunner nb_logs=38 exit_code=1"
      },
      {
        "user": "lestersssss",
        "created_at": "2024-11-07T00:17:25Z",
        "body": "> Check whether your ae.sft (in the vae folder) is complete and uncorrupted. If it is then try uploading an older version - I uploaded a version from September and that solved the isse.\r\n\r\nthank you!"
      },
      {
        "user": "Samchris01",
        "created_at": "2024-11-13T03:04:53Z",
        "body": "> Check whether your ae.sft (in the vae folder) is complete and uncorrupted. If it is then try uploading an older version - I uploaded\r\n\r\nHow to download\r\n"
      },
      {
        "user": "love9678",
        "created_at": "2025-01-06T08:57:21Z",
        "body": "How to download"
      },
      {
        "user": "TijmenJansen0",
        "created_at": "2025-01-26T17:50:58Z",
        "body": "I had the same error after downloading and using the UI locally. \nBug can be fixed by running (in terminal/bash)\nexport PATH=\"/PATH_TO_YOUR_ENVIRONMENT/bin:$PATH\"\n\nbefore running \npython app.py\n"
      }
    ],
    "satisfaction_conditions": [
      "Identifies the root cause of the JSONDecodeError during tokenizer loading",
      "Provides verification methods for model file integrity",
      "Addresses compatibility between model files and training scripts",
      "Covers environment configuration checks"
    ],
    "_classification": {
      "category": "Can be dockerized without any issue",
      "timestamp": "2025-04-05 01:59:20"
    }
  },
  {
    "number": 94,
    "title": "ModuleNotFoundError: No module named 'train_network'",
    "created_at": "2024-09-16T23:33:48Z",
    "closed_at": "2024-09-18T10:04:06Z",
    "labels": [],
    "url": "https://github.com/cocktailpeanut/fluxgym/issues/94",
    "body": "When running `python app.py` after completing manual install steps this error shows. No clue how to resolve, any help would be appreciated\r\n\r\n`ModuleNotFoundError: No module named 'train_network'`",
    "comments_url": "https://api.github.com/repos/cocktailpeanut/fluxgym/issues/94/comments",
    "author": "keizured",
    "comments": [
      {
        "user": "scooper86",
        "created_at": "2024-09-17T00:59:42Z",
        "body": "Same issue for me, installed via git on windows "
      },
      {
        "user": "wuliang19869312",
        "created_at": "2024-09-17T02:20:12Z",
        "body": "Traceback (most recent call last):\r\n  File \"D:\\fluxgym\\app.py\", line 17, in <module>\r\n    import train_network\r\nModuleNotFoundError: No module named 'train_network'\r\nwhy???"
      },
      {
        "user": "one-pip",
        "created_at": "2024-09-17T03:07:05Z",
        "body": "yes, i git pull today , then met this problem"
      },
      {
        "user": "deepfriedheroin",
        "created_at": "2024-09-17T04:04:09Z",
        "body": "I'm sure there's better way to do this, but here. \r\n```\r\nsys.path.append(os.path.abspath('./sd-scripts'))\r\nimport train_network\r\n```"
      },
      {
        "user": "vizuelvfx",
        "created_at": "2024-09-17T11:22:40Z",
        "body": "Wow, thank you!!! that helped me, I didn't know what to do either."
      },
      {
        "user": "one-pip",
        "created_at": "2024-09-17T12:30:09Z",
        "body": "> I'm sure there's better way to do this, but here.\r\n> \r\n> ```\r\n> sys.path.append(os.path.abspath('./sd-scripts'))\r\n> import train_network\r\n> ```\r\n\r\nthanks, i made it"
      },
      {
        "user": "chnisar515",
        "created_at": "2024-09-17T17:55:17Z",
        "body": "i am facing the same error\r\n\r\n> (env) E:\\fluxgym>python app.py\r\nTraceback (most recent call last):\r\n  File \"E:\\fluxgym\\app.py\", line 17, in <module>\r\n    import train_network\r\nModuleNotFoundError: No module named 'train_network'\r\n\r\ncan someone tell me how i can fix this?\r\ni replaced these lines in my app.py file\r\nnow my app.py files looks like below\r\n\r\n> import os\r\nimport sys\r\nimport subprocess\r\nimport gradio as gr\r\nfrom PIL import Image\r\nimport torch\r\nimport uuid\r\nimport shutil\r\nimport json\r\nimport yaml\r\nfrom slugify import slugify\r\nfrom transformers import AutoProcessor, AutoModelForCausalLM\r\nfrom gradio_logsview import LogsView, LogsViewRunner\r\nfrom huggingface_hub import hf_hub_download, HfApi\r\nfrom library import flux_train_utils, huggingface_util\r\nfrom argparse import Namespace\r\nimport train_network\r\nimport toml\r\nimport re\r\nos.environ[\"HF_HUB_ENABLE_HF_TRANSFER\"] = \"1\"\r\nos.environ['GRADIO_ANALYTICS_ENABLED'] = '0'\r\nsys.path.insert(0, os.getcwd())\r\nsys.path.append(os.path.abspath('./sd-scripts'))\r\nimport train_network\r\nMAX_IMAGES = 150"
      },
      {
        "user": "keizured",
        "created_at": "2024-09-18T10:04:06Z",
        "body": "Issue was resolved with latest commit, thank you for fix!"
      }
    ],
    "satisfaction_conditions": [
      "Ensures the 'train_network' module is accessible in the Python path when executing app.py",
      "Resolves discrepancies between the project structure and Python's module resolution logic",
      "Provides a solution that persists across environment setups without manual code edits"
    ],
    "_classification": {
      "category": "Can be dockerized without any issue",
      "timestamp": "2025-04-05 01:59:44"
    }
  }
]